*** Starting uWSGI 2.0.18 (64bit) on [Mon Sep  9 21:11:21 2019] ***
compiled with version: 5.4.0 20160609 on 09 September 2019 13:03:41
os: Linux-4.4.0-93-generic #116-Ubuntu SMP Fri Aug 11 21:17:51 UTC 2017
nodename: iZk5wqwy2o6mkzZ
machine: x86_64
clock source: unix
detected number of CPU cores: 1
current working directory: /home/admin/PUA-master
writing pidfile to uwsgi.pid
detected binary path: /opt/ptyhon3.7/bin/uwsgi
!!! no internal routing support, rebuild with pcre support !!!
uWSGI running as root, you can use --uid/--gid/--chroot options
*** WARNING: you are running uWSGI as root !!! (use the --uid flag) *** 
chdir() to /home/admin/PUA-master
your processes number limit is 7857
your memory page size is 4096 bytes
detected max file descriptor number: 65535
lock engine: pthread robust mutexes
thunder lock: disabled (you can enable it with --thunder-lock)
uWSGI http bound on 0.0.0.0:8000 fd 4
uwsgi socket 0 bound to TCP address 127.0.0.1:39604 (port auto-assigned) fd 3
uWSGI running as root, you can use --uid/--gid/--chroot options
*** WARNING: you are running uWSGI as root !!! (use the --uid flag) *** 
Python version: 3.7.4 (default, Sep  9 2019, 18:03:46)  [GCC 5.4.0 20160609]
Python main interpreter initialized at 0x1c37880
uWSGI running as root, you can use --uid/--gid/--chroot options
*** WARNING: you are running uWSGI as root !!! (use the --uid flag) *** 
python threads support enabled
your server socket listen backlog is limited to 100 connections
your mercy for graceful operations on workers is 60 seconds
mapped 416720 bytes (406 KB) for 8 cores
*** Operational MODE: preforking+threaded ***
WSGI app 0 (mountpoint='') ready in 0 seconds on interpreter 0x1c37880 pid: 1464 (default app)
uWSGI running as root, you can use --uid/--gid/--chroot options
*** WARNING: you are running uWSGI as root !!! (use the --uid flag) *** 
*** uWSGI is running in multiple interpreter mode ***
spawned uWSGI master process (pid: 1464)
spawned uWSGI worker 1 (pid: 1465, cores: 2)
spawned uWSGI worker 2 (pid: 1466, cores: 2)
spawned uWSGI worker 3 (pid: 1467, cores: 2)
spawned uWSGI worker 4 (pid: 1468, cores: 2)
spawned uWSGI http 1 (pid: 1469)
Internal Server Error: /
Traceback (most recent call last):
  File "/opt/ptyhon3.7/lib/python3.7/site-packages/django/core/handlers/exception.py", line 34, in inner
    response = get_response(request)
  File "/opt/ptyhon3.7/lib/python3.7/site-packages/django/core/handlers/base.py", line 100, in _get_response
    resolver_match = resolver.resolve(request.path_info)
  File "/opt/ptyhon3.7/lib/python3.7/site-packages/django/urls/resolvers.py", line 535, in resolve
    for pattern in self.url_patterns:
  File "/opt/ptyhon3.7/lib/python3.7/site-packages/django/utils/functional.py", line 80, in __get__
    res = instance.__dict__[self.name] = self.func(instance)
  File "/opt/ptyhon3.7/lib/python3.7/site-packages/django/urls/resolvers.py", line 579, in url_patterns
    patterns = getattr(self.urlconf_module, "urlpatterns", self.urlconf_module)
  File "/opt/ptyhon3.7/lib/python3.7/site-packages/django/utils/functional.py", line 80, in __get__
    res = instance.__dict__[self.name] = self.func(instance)
  File "/opt/ptyhon3.7/lib/python3.7/site-packages/django/urls/resolvers.py", line 572, in urlconf_module
    return import_module(self.urlconf_name)
  File "/opt/ptyhon3.7/lib/python3.7/importlib/__init__.py", line 127, in import_module
    return _bootstrap._gcd_import(name[level:], package, level)
  File "<frozen importlib._bootstrap>", line 1006, in _gcd_import
  File "<frozen importlib._bootstrap>", line 983, in _find_and_load
  File "<frozen importlib._bootstrap>", line 967, in _find_and_load_unlocked
  File "<frozen importlib._bootstrap>", line 677, in _load_unlocked
  File "<frozen importlib._bootstrap_external>", line 728, in exec_module
  File "<frozen importlib._bootstrap>", line 219, in _call_with_frames_removed
  File "./one/urls.py", line 28, in <module>
  File "/opt/ptyhon3.7/lib/python3.7/site-packages/django/urls/conf.py", line 34, in include
    urlconf_module = import_module(urlconf_module)
  File "/opt/ptyhon3.7/lib/python3.7/importlib/__init__.py", line 127, in import_module
    return _bootstrap._gcd_import(name[level:], package, level)
  File "<frozen importlib._bootstrap>", line 1006, in _gcd_import
  File "<frozen importlib._bootstrap>", line 983, in _find_and_load
  File "<frozen importlib._bootstrap>", line 953, in _find_and_load_unlocked
  File "<frozen importlib._bootstrap>", line 219, in _call_with_frames_removed
  File "<frozen importlib._bootstrap>", line 1006, in _gcd_import
  File "<frozen importlib._bootstrap>", line 983, in _find_and_load
  File "<frozen importlib._bootstrap>", line 965, in _find_and_load_unlocked
ModuleNotFoundError: No module named 'apps.puaheart'
[pid: 1467|app: 0|req: 1/1] 183.192.91.95 () {38 vars in 701 bytes} [Mon Sep  9 21:11:25 2019] GET / => generated 119423 bytes in 124 msecs (HTTP/1.1 500) 4 headers in 130 bytes (1 switches on core 0)
Internal Server Error: /favicon.ico
Traceback (most recent call last):
  File "/opt/ptyhon3.7/lib/python3.7/site-packages/django/core/handlers/exception.py", line 34, in inner
    response = get_response(request)
  File "/opt/ptyhon3.7/lib/python3.7/site-packages/django/utils/deprecation.py", line 93, in __call__
    response = self.process_request(request)
  File "/opt/ptyhon3.7/lib/python3.7/site-packages/django/middleware/common.py", line 52, in process_request
    if self.should_redirect_with_slash(request):
  File "/opt/ptyhon3.7/lib/python3.7/site-packages/django/middleware/common.py", line 70, in should_redirect_with_slash
    not is_valid_path(request.path_info, urlconf) and
  File "/opt/ptyhon3.7/lib/python3.7/site-packages/django/urls/base.py", line 157, in is_valid_path
    resolve(path, urlconf)
  File "/opt/ptyhon3.7/lib/python3.7/site-packages/django/urls/base.py", line 24, in resolve
    return get_resolver(urlconf).resolve(path)
  File "/opt/ptyhon3.7/lib/python3.7/site-packages/django/urls/resolvers.py", line 535, in resolve
    for pattern in self.url_patterns:
  File "/opt/ptyhon3.7/lib/python3.7/site-packages/django/utils/functional.py", line 80, in __get__
    res = instance.__dict__[self.name] = self.func(instance)
  File "/opt/ptyhon3.7/lib/python3.7/site-packages/django/urls/resolvers.py", line 579, in url_patterns
    patterns = getattr(self.urlconf_module, "urlpatterns", self.urlconf_module)
  File "/opt/ptyhon3.7/lib/python3.7/site-packages/django/utils/functional.py", line 80, in __get__
    res = instance.__dict__[self.name] = self.func(instance)
  File "/opt/ptyhon3.7/lib/python3.7/site-packages/django/urls/resolvers.py", line 572, in urlconf_module
    return import_module(self.urlconf_name)
  File "/opt/ptyhon3.7/lib/python3.7/importlib/__init__.py", line 127, in import_module
    return _bootstrap._gcd_import(name[level:], package, level)
  File "<frozen importlib._bootstrap>", line 1006, in _gcd_import
  File "<frozen importlib._bootstrap>", line 983, in _find_and_load
  File "<frozen importlib._bootstrap>", line 965, in _find_and_load_unlocked
ModuleNotFoundError: No module named 'one.urls'
[pid: 1467|app: 0|req: 2/2] 183.192.91.95 () {40 vars in 672 bytes} [Mon Sep  9 21:11:27 2019] GET /favicon.ico => generated 93072 bytes in 35 msecs (HTTP/1.1 500) 1 headers in 63 bytes (1 switches on core 1)
SIGINT/SIGQUIT received...killing workers...
gateway "uWSGI http 1" has been buried (pid: 1469)
worker 1 buried after 1 seconds
worker 2 buried after 1 seconds
worker 3 buried after 1 seconds
worker 4 buried after 1 seconds
goodbye to uWSGI.
*** Starting uWSGI 2.0.18 (64bit) on [Mon Sep  9 21:18:04 2019] ***
compiled with version: 5.4.0 20160609 on 09 September 2019 13:16:32
os: Linux-4.4.0-93-generic #116-Ubuntu SMP Fri Aug 11 21:17:51 UTC 2017
nodename: iZk5wqwy2o6mkzZ
machine: x86_64
clock source: unix
detected number of CPU cores: 1
current working directory: /home/admin/PUA-master
writing pidfile to uwsgi.pid
detected binary path: /home/admin/PUA-master/env/bin/uwsgi
!!! no internal routing support, rebuild with pcre support !!!
uWSGI running as root, you can use --uid/--gid/--chroot options
*** WARNING: you are running uWSGI as root !!! (use the --uid flag) *** 
chdir() to /home/admin/PUA-master
your processes number limit is 7857
your memory page size is 4096 bytes
detected max file descriptor number: 65535
lock engine: pthread robust mutexes
thunder lock: disabled (you can enable it with --thunder-lock)
uWSGI http bound on 0.0.0.0:8000 fd 4
uwsgi socket 0 bound to TCP address 127.0.0.1:37480 (port auto-assigned) fd 3
uWSGI running as root, you can use --uid/--gid/--chroot options
*** WARNING: you are running uWSGI as root !!! (use the --uid flag) *** 
Python version: 3.7.4 (default, Sep  9 2019, 18:03:46)  [GCC 5.4.0 20160609]
Set PythonHome to /home/admin/PUA-master/env
Python main interpreter initialized at 0xb85130
uWSGI running as root, you can use --uid/--gid/--chroot options
*** WARNING: you are running uWSGI as root !!! (use the --uid flag) *** 
python threads support enabled
your server socket listen backlog is limited to 100 connections
your mercy for graceful operations on workers is 60 seconds
mapped 416720 bytes (406 KB) for 8 cores
*** Operational MODE: preforking+threaded ***
WSGI app 0 (mountpoint='') ready in 0 seconds on interpreter 0xb85130 pid: 2252 (default app)
uWSGI running as root, you can use --uid/--gid/--chroot options
*** WARNING: you are running uWSGI as root !!! (use the --uid flag) *** 
*** uWSGI is running in multiple interpreter mode ***
spawned uWSGI master process (pid: 2252)
spawned uWSGI worker 1 (pid: 2253, cores: 2)
spawned uWSGI worker 2 (pid: 2254, cores: 2)
spawned uWSGI worker 3 (pid: 2255, cores: 2)
spawned uWSGI worker 4 (pid: 2256, cores: 2)
spawned uWSGI http 1 (pid: 2257)
Internal Server Error: /
Traceback (most recent call last):
  File "/home/admin/PUA-master/env/lib/python3.7/site-packages/django/core/handlers/exception.py", line 34, in inner
    response = get_response(request)
  File "/home/admin/PUA-master/env/lib/python3.7/site-packages/django/core/handlers/base.py", line 100, in _get_response
    resolver_match = resolver.resolve(request.path_info)
  File "/home/admin/PUA-master/env/lib/python3.7/site-packages/django/urls/resolvers.py", line 535, in resolve
    for pattern in self.url_patterns:
  File "/home/admin/PUA-master/env/lib/python3.7/site-packages/django/utils/functional.py", line 80, in __get__
    res = instance.__dict__[self.name] = self.func(instance)
  File "/home/admin/PUA-master/env/lib/python3.7/site-packages/django/urls/resolvers.py", line 579, in url_patterns
    patterns = getattr(self.urlconf_module, "urlpatterns", self.urlconf_module)
  File "/home/admin/PUA-master/env/lib/python3.7/site-packages/django/utils/functional.py", line 80, in __get__
    res = instance.__dict__[self.name] = self.func(instance)
  File "/home/admin/PUA-master/env/lib/python3.7/site-packages/django/urls/resolvers.py", line 572, in urlconf_module
    return import_module(self.urlconf_name)
  File "/home/admin/PUA-master/env/lib/python3.7/importlib/__init__.py", line 127, in import_module
    return _bootstrap._gcd_import(name[level:], package, level)
  File "<frozen importlib._bootstrap>", line 1006, in _gcd_import
  File "<frozen importlib._bootstrap>", line 983, in _find_and_load
  File "<frozen importlib._bootstrap>", line 967, in _find_and_load_unlocked
  File "<frozen importlib._bootstrap>", line 677, in _load_unlocked
  File "<frozen importlib._bootstrap_external>", line 728, in exec_module
  File "<frozen importlib._bootstrap>", line 219, in _call_with_frames_removed
  File "./one/urls.py", line 28, in <module>
  File "/home/admin/PUA-master/env/lib/python3.7/site-packages/django/urls/conf.py", line 34, in include
    urlconf_module = import_module(urlconf_module)
  File "/home/admin/PUA-master/env/lib/python3.7/importlib/__init__.py", line 127, in import_module
    return _bootstrap._gcd_import(name[level:], package, level)
  File "<frozen importlib._bootstrap>", line 1006, in _gcd_import
  File "<frozen importlib._bootstrap>", line 983, in _find_and_load
  File "<frozen importlib._bootstrap>", line 953, in _find_and_load_unlocked
  File "<frozen importlib._bootstrap>", line 219, in _call_with_frames_removed
  File "<frozen importlib._bootstrap>", line 1006, in _gcd_import
  File "<frozen importlib._bootstrap>", line 983, in _find_and_load
  File "<frozen importlib._bootstrap>", line 965, in _find_and_load_unlocked
ModuleNotFoundError: No module named 'apps.puaheart'
[pid: 2254|app: 0|req: 1/1] 183.192.91.95 () {38 vars in 701 bytes} [Mon Sep  9 21:18:12 2019] GET / => generated 119605 bytes in 105 msecs (HTTP/1.1 500) 4 headers in 130 bytes (1 switches on core 0)
Internal Server Error: /favicon.ico
Traceback (most recent call last):
  File "/home/admin/PUA-master/env/lib/python3.7/site-packages/django/core/handlers/exception.py", line 34, in inner
    response = get_response(request)
  File "/home/admin/PUA-master/env/lib/python3.7/site-packages/django/utils/deprecation.py", line 93, in __call__
    response = self.process_request(request)
  File "/home/admin/PUA-master/env/lib/python3.7/site-packages/django/middleware/common.py", line 52, in process_request
    if self.should_redirect_with_slash(request):
  File "/home/admin/PUA-master/env/lib/python3.7/site-packages/django/middleware/common.py", line 70, in should_redirect_with_slash
    not is_valid_path(request.path_info, urlconf) and
  File "/home/admin/PUA-master/env/lib/python3.7/site-packages/django/urls/base.py", line 157, in is_valid_path
    resolve(path, urlconf)
  File "/home/admin/PUA-master/env/lib/python3.7/site-packages/django/urls/base.py", line 24, in resolve
    return get_resolver(urlconf).resolve(path)
  File "/home/admin/PUA-master/env/lib/python3.7/site-packages/django/urls/resolvers.py", line 535, in resolve
    for pattern in self.url_patterns:
  File "/home/admin/PUA-master/env/lib/python3.7/site-packages/django/utils/functional.py", line 80, in __get__
    res = instance.__dict__[self.name] = self.func(instance)
  File "/home/admin/PUA-master/env/lib/python3.7/site-packages/django/urls/resolvers.py", line 579, in url_patterns
    patterns = getattr(self.urlconf_module, "urlpatterns", self.urlconf_module)
  File "/home/admin/PUA-master/env/lib/python3.7/site-packages/django/utils/functional.py", line 80, in __get__
    res = instance.__dict__[self.name] = self.func(instance)
  File "/home/admin/PUA-master/env/lib/python3.7/site-packages/django/urls/resolvers.py", line 572, in urlconf_module
    return import_module(self.urlconf_name)
  File "/home/admin/PUA-master/env/lib/python3.7/importlib/__init__.py", line 127, in import_module
    return _bootstrap._gcd_import(name[level:], package, level)
  File "<frozen importlib._bootstrap>", line 1006, in _gcd_import
  File "<frozen importlib._bootstrap>", line 983, in _find_and_load
  File "<frozen importlib._bootstrap>", line 965, in _find_and_load_unlocked
ModuleNotFoundError: No module named 'one.urls'
[pid: 2254|app: 0|req: 2/2] 183.192.91.95 () {40 vars in 672 bytes} [Mon Sep  9 21:18:14 2019] GET /favicon.ico => generated 93302 bytes in 34 msecs (HTTP/1.1 500) 1 headers in 63 bytes (1 switches on core 1)
SIGINT/SIGQUIT received...killing workers...
gateway "uWSGI http 1" has been buried (pid: 2257)
worker 1 buried after 1 seconds
worker 2 buried after 1 seconds
worker 3 buried after 1 seconds
worker 4 buried after 1 seconds
goodbye to uWSGI.
*** Starting uWSGI 2.0.18 (64bit) on [Mon Sep  9 21:35:47 2019] ***
compiled with version: 5.4.0 20160609 on 09 September 2019 13:16:32
os: Linux-4.4.0-93-generic #116-Ubuntu SMP Fri Aug 11 21:17:51 UTC 2017
nodename: iZk5wqwy2o6mkzZ
machine: x86_64
clock source: unix
detected number of CPU cores: 1
current working directory: /home/admin/PUA-master
writing pidfile to uwsgi.pid
detected binary path: /home/admin/PUA-master/env/bin/uwsgi
!!! no internal routing support, rebuild with pcre support !!!
uWSGI running as root, you can use --uid/--gid/--chroot options
*** WARNING: you are running uWSGI as root !!! (use the --uid flag) *** 
chdir() to /home/admin/PUA-master
your processes number limit is 7857
your memory page size is 4096 bytes
detected max file descriptor number: 65535
lock engine: pthread robust mutexes
thunder lock: disabled (you can enable it with --thunder-lock)
uWSGI http bound on 0.0.0.0:8000 fd 4
uwsgi socket 0 bound to TCP address 127.0.0.1:34437 (port auto-assigned) fd 3
uWSGI running as root, you can use --uid/--gid/--chroot options
*** WARNING: you are running uWSGI as root !!! (use the --uid flag) *** 
Python version: 3.7.4 (default, Sep  9 2019, 18:03:46)  [GCC 5.4.0 20160609]
Set PythonHome to /home/admin/PUA-master/env
Python main interpreter initialized at 0xb07140
uWSGI running as root, you can use --uid/--gid/--chroot options
*** WARNING: you are running uWSGI as root !!! (use the --uid flag) *** 
python threads support enabled
your server socket listen backlog is limited to 100 connections
your mercy for graceful operations on workers is 60 seconds
mapped 166688 bytes (162 KB) for 2 cores
*** Operational MODE: threaded ***
WSGI app 0 (mountpoint='') ready in 0 seconds on interpreter 0xb07140 pid: 2483 (default app)
uWSGI running as root, you can use --uid/--gid/--chroot options
*** WARNING: you are running uWSGI as root !!! (use the --uid flag) *** 
*** uWSGI is running in multiple interpreter mode ***
spawned uWSGI master process (pid: 2483)
spawned uWSGI worker 1 (pid: 2484, cores: 2)
spawned uWSGI http 1 (pid: 2485)
Traceback (most recent call last):
  File "/home/admin/PUA-master/env/lib/python3.7/site-packages/django/core/handlers/exception.py", line 34, in inner
    response = get_response(request)
  File "/home/admin/PUA-master/env/lib/python3.7/site-packages/django/core/handlers/base.py", line 100, in _get_response
    resolver_match = resolver.resolve(request.path_info)
  File "/home/admin/PUA-master/env/lib/python3.7/site-packages/django/urls/resolvers.py", line 535, in resolve
    for pattern in self.url_patterns:
  File "/home/admin/PUA-master/env/lib/python3.7/site-packages/django/utils/functional.py", line 80, in __get__
    res = instance.__dict__[self.name] = self.func(instance)
  File "/home/admin/PUA-master/env/lib/python3.7/site-packages/django/urls/resolvers.py", line 579, in url_patterns
    patterns = getattr(self.urlconf_module, "urlpatterns", self.urlconf_module)
  File "/home/admin/PUA-master/env/lib/python3.7/site-packages/django/utils/functional.py", line 80, in __get__
    res = instance.__dict__[self.name] = self.func(instance)
  File "/home/admin/PUA-master/env/lib/python3.7/site-packages/django/urls/resolvers.py", line 572, in urlconf_module
    return import_module(self.urlconf_name)
  File "/home/admin/PUA-master/env/lib/python3.7/importlib/__init__.py", line 127, in import_module
    return _bootstrap._gcd_import(name[level:], package, level)
  File "<frozen importlib._bootstrap>", line 1006, in _gcd_import
  File "<frozen importlib._bootstrap>", line 983, in _find_and_load
  File "<frozen importlib._bootstrap>", line 967, in _find_and_load_unlocked
  File "<frozen importlib._bootstrap>", line 677, in _load_unlocked
  File "<frozen importlib._bootstrap_external>", line 728, in exec_module
  File "<frozen importlib._bootstrap>", line 219, in _call_with_frames_removed
  File "./one/urls.py", line 28, in <module>
  File "/home/admin/PUA-master/env/lib/python3.7/site-packages/django/urls/conf.py", line 34, in include
    urlconf_module = import_module(urlconf_module)
  File "/home/admin/PUA-master/env/lib/python3.7/importlib/__init__.py", line 127, in import_module
    return _bootstrap._gcd_import(name[level:], package, level)
  File "<frozen importlib._bootstrap>", line 1006, in _gcd_import
  File "<frozen importlib._bootstrap>", line 983, in _find_and_load
  File "<frozen importlib._bootstrap>", line 953, in _find_and_load_unlocked
  File "<frozen importlib._bootstrap>", line 219, in _call_with_frames_removed
  File "<frozen importlib._bootstrap>", line 1006, in _gcd_import
  File "<frozen importlib._bootstrap>", line 983, in _find_and_load
  File "<frozen importlib._bootstrap>", line 965, in _find_and_load_unlocked
ModuleNotFoundError: No module named 'apps.puaheart'

During handling of the above exception, another exception occurred:

Traceback (most recent call last):
  File "/home/admin/PUA-master/env/lib/python3.7/site-packages/django/core/handlers/exception.py", line 34, in inner
    response = get_response(request)
  File "/home/admin/PUA-master/env/lib/python3.7/site-packages/django/utils/deprecation.py", line 94, in __call__
    response = response or self.get_response(request)
  File "/home/admin/PUA-master/env/lib/python3.7/site-packages/django/core/handlers/exception.py", line 36, in inner
    response = response_for_exception(request, exc)
  File "/home/admin/PUA-master/env/lib/python3.7/site-packages/django/core/handlers/exception.py", line 90, in response_for_exception
    response = handle_uncaught_exception(request, get_resolver(get_urlconf()), sys.exc_info())
  File "/home/admin/PUA-master/env/lib/python3.7/site-packages/django/core/handlers/exception.py", line 128, in handle_uncaught_exception
    callback, param_dict = resolver.resolve_error_handler(500)
  File "/home/admin/PUA-master/env/lib/python3.7/site-packages/django/urls/resolvers.py", line 592, in resolve_error_handler
    callback = getattr(self.urlconf_module, 'handler%s' % view_type, None)
  File "/home/admin/PUA-master/env/lib/python3.7/site-packages/django/utils/functional.py", line 80, in __get__
    res = instance.__dict__[self.name] = self.func(instance)
  File "/home/admin/PUA-master/env/lib/python3.7/site-packages/django/urls/resolvers.py", line 572, in urlconf_module
    return import_module(self.urlconf_name)
  File "/home/admin/PUA-master/env/lib/python3.7/importlib/__init__.py", line 127, in import_module
    return _bootstrap._gcd_import(name[level:], package, level)
  File "<frozen importlib._bootstrap>", line 1006, in _gcd_import
  File "<frozen importlib._bootstrap>", line 983, in _find_and_load
  File "<frozen importlib._bootstrap>", line 965, in _find_and_load_unlocked
ModuleNotFoundError: No module named 'one.urls'

During handling of the above exception, another exception occurred:

Traceback (most recent call last):
  File "/home/admin/PUA-master/env/lib/python3.7/site-packages/django/core/handlers/exception.py", line 34, in inner
    response = get_response(request)
  File "/home/admin/PUA-master/env/lib/python3.7/site-packages/django/utils/deprecation.py", line 94, in __call__
    response = response or self.get_response(request)
  File "/home/admin/PUA-master/env/lib/python3.7/site-packages/django/core/handlers/exception.py", line 36, in inner
    response = response_for_exception(request, exc)
  File "/home/admin/PUA-master/env/lib/python3.7/site-packages/django/core/handlers/exception.py", line 90, in response_for_exception
    response = handle_uncaught_exception(request, get_resolver(get_urlconf()), sys.exc_info())
  File "/home/admin/PUA-master/env/lib/python3.7/site-packages/django/core/handlers/exception.py", line 128, in handle_uncaught_exception
    callback, param_dict = resolver.resolve_error_handler(500)
  File "/home/admin/PUA-master/env/lib/python3.7/site-packages/django/urls/resolvers.py", line 592, in resolve_error_handler
    callback = getattr(self.urlconf_module, 'handler%s' % view_type, None)
  File "/home/admin/PUA-master/env/lib/python3.7/site-packages/django/utils/functional.py", line 80, in __get__
    res = instance.__dict__[self.name] = self.func(instance)
  File "/home/admin/PUA-master/env/lib/python3.7/site-packages/django/urls/resolvers.py", line 572, in urlconf_module
    return import_module(self.urlconf_name)
  File "/home/admin/PUA-master/env/lib/python3.7/importlib/__init__.py", line 127, in import_module
    return _bootstrap._gcd_import(name[level:], package, level)
  File "<frozen importlib._bootstrap>", line 1006, in _gcd_import
  File "<frozen importlib._bootstrap>", line 983, in _find_and_load
  File "<frozen importlib._bootstrap>", line 965, in _find_and_load_unlocked
ModuleNotFoundError: No module named 'one.urls'

During handling of the above exception, another exception occurred:

Traceback (most recent call last):
  File "/home/admin/PUA-master/env/lib/python3.7/site-packages/django/core/handlers/exception.py", line 34, in inner
    response = get_response(request)
  File "/home/admin/PUA-master/env/lib/python3.7/site-packages/django/utils/deprecation.py", line 94, in __call__
    response = response or self.get_response(request)
  File "/home/admin/PUA-master/env/lib/python3.7/site-packages/django/core/handlers/exception.py", line 36, in inner
    response = response_for_exception(request, exc)
  File "/home/admin/PUA-master/env/lib/python3.7/site-packages/django/core/handlers/exception.py", line 90, in response_for_exception
    response = handle_uncaught_exception(request, get_resolver(get_urlconf()), sys.exc_info())
  File "/home/admin/PUA-master/env/lib/python3.7/site-packages/django/core/handlers/exception.py", line 128, in handle_uncaught_exception
    callback, param_dict = resolver.resolve_error_handler(500)
  File "/home/admin/PUA-master/env/lib/python3.7/site-packages/django/urls/resolvers.py", line 592, in resolve_error_handler
    callback = getattr(self.urlconf_module, 'handler%s' % view_type, None)
  File "/home/admin/PUA-master/env/lib/python3.7/site-packages/django/utils/functional.py", line 80, in __get__
    res = instance.__dict__[self.name] = self.func(instance)
  File "/home/admin/PUA-master/env/lib/python3.7/site-packages/django/urls/resolvers.py", line 572, in urlconf_module
    return import_module(self.urlconf_name)
  File "/home/admin/PUA-master/env/lib/python3.7/importlib/__init__.py", line 127, in import_module
    return _bootstrap._gcd_import(name[level:], package, level)
  File "<frozen importlib._bootstrap>", line 1006, in _gcd_import
  File "<frozen importlib._bootstrap>", line 983, in _find_and_load
  File "<frozen importlib._bootstrap>", line 965, in _find_and_load_unlocked
ModuleNotFoundError: No module named 'one.urls'

During handling of the above exception, another exception occurred:

Traceback (most recent call last):
  File "/home/admin/PUA-master/env/lib/python3.7/site-packages/django/core/handlers/exception.py", line 34, in inner
    response = get_response(request)
  File "/home/admin/PUA-master/env/lib/python3.7/site-packages/django/utils/deprecation.py", line 94, in __call__
    response = response or self.get_response(request)
  File "/home/admin/PUA-master/env/lib/python3.7/site-packages/django/core/handlers/exception.py", line 36, in inner
    response = response_for_exception(request, exc)
  File "/home/admin/PUA-master/env/lib/python3.7/site-packages/django/core/handlers/exception.py", line 90, in response_for_exception
    response = handle_uncaught_exception(request, get_resolver(get_urlconf()), sys.exc_info())
  File "/home/admin/PUA-master/env/lib/python3.7/site-packages/django/core/handlers/exception.py", line 128, in handle_uncaught_exception
    callback, param_dict = resolver.resolve_error_handler(500)
  File "/home/admin/PUA-master/env/lib/python3.7/site-packages/django/urls/resolvers.py", line 592, in resolve_error_handler
    callback = getattr(self.urlconf_module, 'handler%s' % view_type, None)
  File "/home/admin/PUA-master/env/lib/python3.7/site-packages/django/utils/functional.py", line 80, in __get__
    res = instance.__dict__[self.name] = self.func(instance)
  File "/home/admin/PUA-master/env/lib/python3.7/site-packages/django/urls/resolvers.py", line 572, in urlconf_module
    return import_module(self.urlconf_name)
  File "/home/admin/PUA-master/env/lib/python3.7/importlib/__init__.py", line 127, in import_module
    return _bootstrap._gcd_import(name[level:], package, level)
  File "<frozen importlib._bootstrap>", line 1006, in _gcd_import
  File "<frozen importlib._bootstrap>", line 983, in _find_and_load
  File "<frozen importlib._bootstrap>", line 965, in _find_and_load_unlocked
ModuleNotFoundError: No module named 'one.urls'

During handling of the above exception, another exception occurred:

Traceback (most recent call last):
  File "/home/admin/PUA-master/env/lib/python3.7/site-packages/django/core/handlers/exception.py", line 34, in inner
    response = get_response(request)
  File "/home/admin/PUA-master/env/lib/python3.7/site-packages/django/utils/deprecation.py", line 94, in __call__
    response = response or self.get_response(request)
  File "/home/admin/PUA-master/env/lib/python3.7/site-packages/django/core/handlers/exception.py", line 36, in inner
    response = response_for_exception(request, exc)
  File "/home/admin/PUA-master/env/lib/python3.7/site-packages/django/core/handlers/exception.py", line 90, in response_for_exception
    response = handle_uncaught_exception(request, get_resolver(get_urlconf()), sys.exc_info())
  File "/home/admin/PUA-master/env/lib/python3.7/site-packages/django/core/handlers/exception.py", line 128, in handle_uncaught_exception
    callback, param_dict = resolver.resolve_error_handler(500)
  File "/home/admin/PUA-master/env/lib/python3.7/site-packages/django/urls/resolvers.py", line 592, in resolve_error_handler
    callback = getattr(self.urlconf_module, 'handler%s' % view_type, None)
  File "/home/admin/PUA-master/env/lib/python3.7/site-packages/django/utils/functional.py", line 80, in __get__
    res = instance.__dict__[self.name] = self.func(instance)
  File "/home/admin/PUA-master/env/lib/python3.7/site-packages/django/urls/resolvers.py", line 572, in urlconf_module
    return import_module(self.urlconf_name)
  File "/home/admin/PUA-master/env/lib/python3.7/importlib/__init__.py", line 127, in import_module
    return _bootstrap._gcd_import(name[level:], package, level)
  File "<frozen importlib._bootstrap>", line 1006, in _gcd_import
  File "<frozen importlib._bootstrap>", line 983, in _find_and_load
  File "<frozen importlib._bootstrap>", line 965, in _find_and_load_unlocked
ModuleNotFoundError: No module named 'one.urls'

During handling of the above exception, another exception occurred:

Traceback (most recent call last):
  File "/home/admin/PUA-master/env/lib/python3.7/site-packages/django/core/handlers/exception.py", line 34, in inner
    response = get_response(request)
  File "/home/admin/PUA-master/env/lib/python3.7/site-packages/django/utils/deprecation.py", line 94, in __call__
    response = response or self.get_response(request)
  File "/home/admin/PUA-master/env/lib/python3.7/site-packages/django/core/handlers/exception.py", line 36, in inner
    response = response_for_exception(request, exc)
  File "/home/admin/PUA-master/env/lib/python3.7/site-packages/django/core/handlers/exception.py", line 90, in response_for_exception
    response = handle_uncaught_exception(request, get_resolver(get_urlconf()), sys.exc_info())
  File "/home/admin/PUA-master/env/lib/python3.7/site-packages/django/core/handlers/exception.py", line 128, in handle_uncaught_exception
    callback, param_dict = resolver.resolve_error_handler(500)
  File "/home/admin/PUA-master/env/lib/python3.7/site-packages/django/urls/resolvers.py", line 592, in resolve_error_handler
    callback = getattr(self.urlconf_module, 'handler%s' % view_type, None)
  File "/home/admin/PUA-master/env/lib/python3.7/site-packages/django/utils/functional.py", line 80, in __get__
    res = instance.__dict__[self.name] = self.func(instance)
  File "/home/admin/PUA-master/env/lib/python3.7/site-packages/django/urls/resolvers.py", line 572, in urlconf_module
    return import_module(self.urlconf_name)
  File "/home/admin/PUA-master/env/lib/python3.7/importlib/__init__.py", line 127, in import_module
    return _bootstrap._gcd_import(name[level:], package, level)
  File "<frozen importlib._bootstrap>", line 1006, in _gcd_import
  File "<frozen importlib._bootstrap>", line 983, in _find_and_load
  File "<frozen importlib._bootstrap>", line 965, in _find_and_load_unlocked
ModuleNotFoundError: No module named 'one.urls'

During handling of the above exception, another exception occurred:

Traceback (most recent call last):
  File "/home/admin/PUA-master/env/lib/python3.7/site-packages/django/core/handlers/exception.py", line 34, in inner
    response = get_response(request)
  File "/home/admin/PUA-master/env/lib/python3.7/site-packages/django/utils/deprecation.py", line 94, in __call__
    response = response or self.get_response(request)
  File "/home/admin/PUA-master/env/lib/python3.7/site-packages/django/core/handlers/exception.py", line 36, in inner
    response = response_for_exception(request, exc)
  File "/home/admin/PUA-master/env/lib/python3.7/site-packages/django/core/handlers/exception.py", line 90, in response_for_exception
    response = handle_uncaught_exception(request, get_resolver(get_urlconf()), sys.exc_info())
  File "/home/admin/PUA-master/env/lib/python3.7/site-packages/django/core/handlers/exception.py", line 128, in handle_uncaught_exception
    callback, param_dict = resolver.resolve_error_handler(500)
  File "/home/admin/PUA-master/env/lib/python3.7/site-packages/django/urls/resolvers.py", line 592, in resolve_error_handler
    callback = getattr(self.urlconf_module, 'handler%s' % view_type, None)
  File "/home/admin/PUA-master/env/lib/python3.7/site-packages/django/utils/functional.py", line 80, in __get__
    res = instance.__dict__[self.name] = self.func(instance)
  File "/home/admin/PUA-master/env/lib/python3.7/site-packages/django/urls/resolvers.py", line 572, in urlconf_module
    return import_module(self.urlconf_name)
  File "/home/admin/PUA-master/env/lib/python3.7/importlib/__init__.py", line 127, in import_module
    return _bootstrap._gcd_import(name[level:], package, level)
  File "<frozen importlib._bootstrap>", line 1006, in _gcd_import
  File "<frozen importlib._bootstrap>", line 983, in _find_and_load
  File "<frozen importlib._bootstrap>", line 965, in _find_and_load_unlocked
ModuleNotFoundError: No module named 'one.urls'

During handling of the above exception, another exception occurred:

Traceback (most recent call last):
  File "/home/admin/PUA-master/env/lib/python3.7/site-packages/django/core/handlers/wsgi.py", line 141, in __call__
    response = self.get_response(request)
  File "/home/admin/PUA-master/env/lib/python3.7/site-packages/django/core/handlers/base.py", line 75, in get_response
    response = self._middleware_chain(request)
  File "/home/admin/PUA-master/env/lib/python3.7/site-packages/django/core/handlers/exception.py", line 36, in inner
    response = response_for_exception(request, exc)
  File "/home/admin/PUA-master/env/lib/python3.7/site-packages/django/core/handlers/exception.py", line 90, in response_for_exception
    response = handle_uncaught_exception(request, get_resolver(get_urlconf()), sys.exc_info())
  File "/home/admin/PUA-master/env/lib/python3.7/site-packages/django/core/handlers/exception.py", line 128, in handle_uncaught_exception
    callback, param_dict = resolver.resolve_error_handler(500)
  File "/home/admin/PUA-master/env/lib/python3.7/site-packages/django/urls/resolvers.py", line 592, in resolve_error_handler
    callback = getattr(self.urlconf_module, 'handler%s' % view_type, None)
  File "/home/admin/PUA-master/env/lib/python3.7/site-packages/django/utils/functional.py", line 80, in __get__
    res = instance.__dict__[self.name] = self.func(instance)
  File "/home/admin/PUA-master/env/lib/python3.7/site-packages/django/urls/resolvers.py", line 572, in urlconf_module
    return import_module(self.urlconf_name)
  File "/home/admin/PUA-master/env/lib/python3.7/importlib/__init__.py", line 127, in import_module
    return _bootstrap._gcd_import(name[level:], package, level)
  File "<frozen importlib._bootstrap>", line 1006, in _gcd_import
  File "<frozen importlib._bootstrap>", line 983, in _find_and_load
  File "<frozen importlib._bootstrap>", line 965, in _find_and_load_unlocked
ModuleNotFoundError: No module named 'one.urls'
[pid: 2484|app: 0|req: 1/1] 183.192.91.95 () {38 vars in 702 bytes} [Mon Sep  9 21:35:51 2019] GET / => generated 0 bytes in 62 msecs (HTTP/1.1 500) 0 headers in 0 bytes (0 switches on core 0)
SIGINT/SIGQUIT received...killing workers...
gateway "uWSGI http 1" has been buried (pid: 2485)
worker 1 buried after 1 seconds
goodbye to uWSGI.
*** Starting uWSGI 2.0.18 (64bit) on [Mon Sep  9 21:37:30 2019] ***
compiled with version: 5.4.0 20160609 on 09 September 2019 13:16:32
os: Linux-4.4.0-93-generic #116-Ubuntu SMP Fri Aug 11 21:17:51 UTC 2017
nodename: iZk5wqwy2o6mkzZ
machine: x86_64
clock source: unix
detected number of CPU cores: 1
current working directory: /home/admin/PUA-master
writing pidfile to uwsgi.pid
detected binary path: /home/admin/PUA-master/env/bin/uwsgi
!!! no internal routing support, rebuild with pcre support !!!
uWSGI running as root, you can use --uid/--gid/--chroot options
*** WARNING: you are running uWSGI as root !!! (use the --uid flag) *** 
chdir() to /home/admin/PUA-master
your processes number limit is 7857
your memory page size is 4096 bytes
detected max file descriptor number: 65535
lock engine: pthread robust mutexes
thunder lock: disabled (you can enable it with --thunder-lock)
uWSGI http bound on 0.0.0.0:8000 fd 4
uwsgi socket 0 bound to TCP address 127.0.0.1:36642 (port auto-assigned) fd 3
uWSGI running as root, you can use --uid/--gid/--chroot options
*** WARNING: you are running uWSGI as root !!! (use the --uid flag) *** 
Python version: 3.7.4 (default, Sep  9 2019, 18:03:46)  [GCC 5.4.0 20160609]
Set PythonHome to /home/admin/PUA-master/env
Python main interpreter initialized at 0x2561140
uWSGI running as root, you can use --uid/--gid/--chroot options
*** WARNING: you are running uWSGI as root !!! (use the --uid flag) *** 
python threads support enabled
your server socket listen backlog is limited to 100 connections
your mercy for graceful operations on workers is 60 seconds
mapped 166688 bytes (162 KB) for 2 cores
*** Operational MODE: threaded ***
WSGI app 0 (mountpoint='') ready in 0 seconds on interpreter 0x2561140 pid: 2516 (default app)
uWSGI running as root, you can use --uid/--gid/--chroot options
*** WARNING: you are running uWSGI as root !!! (use the --uid flag) *** 
*** uWSGI is running in multiple interpreter mode ***
spawned uWSGI master process (pid: 2516)
spawned uWSGI worker 1 (pid: 2517, cores: 2)
spawned uWSGI http 1 (pid: 2518)
Internal Server Error: /
Traceback (most recent call last):
  File "/home/admin/PUA-master/env/lib/python3.7/site-packages/django/core/handlers/exception.py", line 34, in inner
    response = get_response(request)
  File "/home/admin/PUA-master/env/lib/python3.7/site-packages/django/core/handlers/base.py", line 100, in _get_response
    resolver_match = resolver.resolve(request.path_info)
  File "/home/admin/PUA-master/env/lib/python3.7/site-packages/django/urls/resolvers.py", line 535, in resolve
    for pattern in self.url_patterns:
  File "/home/admin/PUA-master/env/lib/python3.7/site-packages/django/utils/functional.py", line 80, in __get__
    res = instance.__dict__[self.name] = self.func(instance)
  File "/home/admin/PUA-master/env/lib/python3.7/site-packages/django/urls/resolvers.py", line 579, in url_patterns
    patterns = getattr(self.urlconf_module, "urlpatterns", self.urlconf_module)
  File "/home/admin/PUA-master/env/lib/python3.7/site-packages/django/utils/functional.py", line 80, in __get__
    res = instance.__dict__[self.name] = self.func(instance)
  File "/home/admin/PUA-master/env/lib/python3.7/site-packages/django/urls/resolvers.py", line 572, in urlconf_module
    return import_module(self.urlconf_name)
  File "/home/admin/PUA-master/env/lib/python3.7/importlib/__init__.py", line 127, in import_module
    return _bootstrap._gcd_import(name[level:], package, level)
  File "<frozen importlib._bootstrap>", line 1006, in _gcd_import
  File "<frozen importlib._bootstrap>", line 983, in _find_and_load
  File "<frozen importlib._bootstrap>", line 967, in _find_and_load_unlocked
  File "<frozen importlib._bootstrap>", line 677, in _load_unlocked
  File "<frozen importlib._bootstrap_external>", line 728, in exec_module
  File "<frozen importlib._bootstrap>", line 219, in _call_with_frames_removed
  File "./one/urls.py", line 28, in <module>
  File "/home/admin/PUA-master/env/lib/python3.7/site-packages/django/urls/conf.py", line 34, in include
    urlconf_module = import_module(urlconf_module)
  File "/home/admin/PUA-master/env/lib/python3.7/importlib/__init__.py", line 127, in import_module
    return _bootstrap._gcd_import(name[level:], package, level)
  File "<frozen importlib._bootstrap>", line 1006, in _gcd_import
  File "<frozen importlib._bootstrap>", line 983, in _find_and_load
  File "<frozen importlib._bootstrap>", line 953, in _find_and_load_unlocked
  File "<frozen importlib._bootstrap>", line 219, in _call_with_frames_removed
  File "<frozen importlib._bootstrap>", line 1006, in _gcd_import
  File "<frozen importlib._bootstrap>", line 983, in _find_and_load
  File "<frozen importlib._bootstrap>", line 965, in _find_and_load_unlocked
ModuleNotFoundError: No module named 'apps.puaheart'
[pid: 2517|app: 0|req: 1/1] 183.192.91.95 () {38 vars in 701 bytes} [Mon Sep  9 21:37:34 2019] GET / => generated 119606 bytes in 100 msecs (HTTP/1.1 500) 4 headers in 130 bytes (1 switches on core 0)
SIGINT/SIGQUIT received...killing workers...
gateway "uWSGI http 1" has been buried (pid: 2518)
worker 1 buried after 1 seconds
goodbye to uWSGI.
*** Starting uWSGI 2.0.18 (64bit) on [Mon Sep  9 21:38:35 2019] ***
compiled with version: 5.4.0 20160609 on 09 September 2019 13:16:32
os: Linux-4.4.0-93-generic #116-Ubuntu SMP Fri Aug 11 21:17:51 UTC 2017
nodename: iZk5wqwy2o6mkzZ
machine: x86_64
clock source: unix
detected number of CPU cores: 1
current working directory: /home/admin/PUA-master
writing pidfile to uwsgi.pid
detected binary path: /home/admin/PUA-master/env/bin/uwsgi
!!! no internal routing support, rebuild with pcre support !!!
uWSGI running as root, you can use --uid/--gid/--chroot options
*** WARNING: you are running uWSGI as root !!! (use the --uid flag) *** 
chdir() to /home/admin/PUA-master
your processes number limit is 7857
your memory page size is 4096 bytes
detected max file descriptor number: 65535
lock engine: pthread robust mutexes
thunder lock: disabled (you can enable it with --thunder-lock)
uWSGI http bound on 0.0.0.0:8000 fd 4
uwsgi socket 0 bound to TCP address 127.0.0.1:44669 (port auto-assigned) fd 3
uWSGI running as root, you can use --uid/--gid/--chroot options
*** WARNING: you are running uWSGI as root !!! (use the --uid flag) *** 
Python version: 3.7.4 (default, Sep  9 2019, 18:03:46)  [GCC 5.4.0 20160609]
Set PythonHome to /home/admin/PUA-master/env
Python main interpreter initialized at 0xfec140
uWSGI running as root, you can use --uid/--gid/--chroot options
*** WARNING: you are running uWSGI as root !!! (use the --uid flag) *** 
python threads support enabled
your server socket listen backlog is limited to 100 connections
your mercy for graceful operations on workers is 60 seconds
mapped 166688 bytes (162 KB) for 2 cores
*** Operational MODE: threaded ***
WSGI app 0 (mountpoint='') ready in 0 seconds on interpreter 0xfec140 pid: 2546 (default app)
uWSGI running as root, you can use --uid/--gid/--chroot options
*** WARNING: you are running uWSGI as root !!! (use the --uid flag) *** 
*** uWSGI is running in multiple interpreter mode ***
spawned uWSGI master process (pid: 2546)
spawned uWSGI worker 1 (pid: 2547, cores: 2)
spawned uWSGI http 1 (pid: 2548)
Internal Server Error: /
Traceback (most recent call last):
  File "/home/admin/PUA-master/env/lib/python3.7/site-packages/django/core/handlers/exception.py", line 34, in inner
    response = get_response(request)
  File "/home/admin/PUA-master/env/lib/python3.7/site-packages/django/core/handlers/base.py", line 100, in _get_response
    resolver_match = resolver.resolve(request.path_info)
  File "/home/admin/PUA-master/env/lib/python3.7/site-packages/django/urls/resolvers.py", line 535, in resolve
    for pattern in self.url_patterns:
  File "/home/admin/PUA-master/env/lib/python3.7/site-packages/django/utils/functional.py", line 80, in __get__
    res = instance.__dict__[self.name] = self.func(instance)
  File "/home/admin/PUA-master/env/lib/python3.7/site-packages/django/urls/resolvers.py", line 579, in url_patterns
    patterns = getattr(self.urlconf_module, "urlpatterns", self.urlconf_module)
  File "/home/admin/PUA-master/env/lib/python3.7/site-packages/django/utils/functional.py", line 80, in __get__
    res = instance.__dict__[self.name] = self.func(instance)
  File "/home/admin/PUA-master/env/lib/python3.7/site-packages/django/urls/resolvers.py", line 572, in urlconf_module
    return import_module(self.urlconf_name)
  File "/home/admin/PUA-master/env/lib/python3.7/importlib/__init__.py", line 127, in import_module
    return _bootstrap._gcd_import(name[level:], package, level)
  File "<frozen importlib._bootstrap>", line 1006, in _gcd_import
  File "<frozen importlib._bootstrap>", line 983, in _find_and_load
  File "<frozen importlib._bootstrap>", line 967, in _find_and_load_unlocked
  File "<frozen importlib._bootstrap>", line 677, in _load_unlocked
  File "<frozen importlib._bootstrap_external>", line 728, in exec_module
  File "<frozen importlib._bootstrap>", line 219, in _call_with_frames_removed
  File "./one/urls.py", line 28, in <module>
  File "/home/admin/PUA-master/env/lib/python3.7/site-packages/django/urls/conf.py", line 34, in include
    urlconf_module = import_module(urlconf_module)
  File "/home/admin/PUA-master/env/lib/python3.7/importlib/__init__.py", line 127, in import_module
    return _bootstrap._gcd_import(name[level:], package, level)
  File "<frozen importlib._bootstrap>", line 1006, in _gcd_import
  File "<frozen importlib._bootstrap>", line 983, in _find_and_load
  File "<frozen importlib._bootstrap>", line 965, in _find_and_load_unlocked
ModuleNotFoundError: No module named 'apps.puaheart.urls'
[pid: 2547|app: 0|req: 1/1] 183.192.91.95 () {38 vars in 702 bytes} [Mon Sep  9 21:38:40 2019] GET / => generated 112862 bytes in 100 msecs (HTTP/1.1 500) 4 headers in 130 bytes (1 switches on core 0)
Internal Server Error: /favicon.ico
Traceback (most recent call last):
  File "/home/admin/PUA-master/env/lib/python3.7/site-packages/django/core/handlers/exception.py", line 34, in inner
    response = get_response(request)
  File "/home/admin/PUA-master/env/lib/python3.7/site-packages/django/utils/deprecation.py", line 93, in __call__
    response = self.process_request(request)
  File "/home/admin/PUA-master/env/lib/python3.7/site-packages/django/middleware/common.py", line 52, in process_request
    if self.should_redirect_with_slash(request):
  File "/home/admin/PUA-master/env/lib/python3.7/site-packages/django/middleware/common.py", line 70, in should_redirect_with_slash
    not is_valid_path(request.path_info, urlconf) and
  File "/home/admin/PUA-master/env/lib/python3.7/site-packages/django/urls/base.py", line 157, in is_valid_path
    resolve(path, urlconf)
  File "/home/admin/PUA-master/env/lib/python3.7/site-packages/django/urls/base.py", line 24, in resolve
    return get_resolver(urlconf).resolve(path)
  File "/home/admin/PUA-master/env/lib/python3.7/site-packages/django/urls/resolvers.py", line 535, in resolve
    for pattern in self.url_patterns:
  File "/home/admin/PUA-master/env/lib/python3.7/site-packages/django/utils/functional.py", line 80, in __get__
    res = instance.__dict__[self.name] = self.func(instance)
  File "/home/admin/PUA-master/env/lib/python3.7/site-packages/django/urls/resolvers.py", line 579, in url_patterns
    patterns = getattr(self.urlconf_module, "urlpatterns", self.urlconf_module)
  File "/home/admin/PUA-master/env/lib/python3.7/site-packages/django/utils/functional.py", line 80, in __get__
    res = instance.__dict__[self.name] = self.func(instance)
  File "/home/admin/PUA-master/env/lib/python3.7/site-packages/django/urls/resolvers.py", line 572, in urlconf_module
    return import_module(self.urlconf_name)
  File "/home/admin/PUA-master/env/lib/python3.7/importlib/__init__.py", line 127, in import_module
    return _bootstrap._gcd_import(name[level:], package, level)
  File "<frozen importlib._bootstrap>", line 1006, in _gcd_import
  File "<frozen importlib._bootstrap>", line 983, in _find_and_load
  File "<frozen importlib._bootstrap>", line 965, in _find_and_load_unlocked
ModuleNotFoundError: No module named 'one.urls'
[pid: 2547|app: 0|req: 2/2] 183.192.91.95 () {40 vars in 673 bytes} [Mon Sep  9 21:38:40 2019] GET /favicon.ico => generated 93356 bytes in 33 msecs (HTTP/1.1 500) 1 headers in 63 bytes (1 switches on core 1)
SIGINT/SIGQUIT received...killing workers...
gateway "uWSGI http 1" has been buried (pid: 2548)
worker 1 buried after 1 seconds
goodbye to uWSGI.
